<?xml version="1.0"?>
<!--
  Bipedal Humanoid Robot - URDF Model
  Module 1: The Robotic Nervous System
  
  This URDF defines a simple bipedal humanoid robot with:
  - A base/torso link
  - Two legs with hip, knee, and ankle joints
  - Two arms with shoulder, elbow, and wrist joints
  - A head with a neck joint
  
  Usage:
    ros2 launch urdf_tutorial display.launch.py model:=bipedal_robot.urdf
-->
<robot name="bipedal_humanoid">
  
  <!-- ========== MATERIALS ========== -->
  <material name="blue">
    <color rgba="0.0 0.5 1.0 1.0"/>
  </material>
  
  <material name="dark_gray">
    <color rgba="0.3 0.3 0.3 1.0"/>
  </material>
  
  <material name="light_gray">
    <color rgba="0.7 0.7 0.7 1.0"/>
  </material>
  
  <material name="cyan">
    <color rgba="0.0 0.8 0.8 1.0"/>
  </material>
  
  <!-- ========== BASE/TORSO ========== -->
  <link name="base_link">
    <visual>
      <geometry>
        <box size="0.3 0.4 0.5"/>
      </geometry>
      <origin xyz="0 0 0.9" rpy="0 0 0"/>
      <material name="blue"/>
    </visual>
    <collision>
      <geometry>
        <box size="0.3 0.4 0.5"/>
      </geometry>
      <origin xyz="0 0 0.9" rpy="0 0 0"/>
    </collision>
    <inertial>
      <mass value="10.0"/>
      <inertia ixx="0.5" ixy="0" ixz="0" iyy="0.5" iyz="0" izz="0.3"/>
    </inertial>
  </link>
  
  <!-- ========== HEAD ========== -->
  <link name="head">
    <visual>
      <geometry>
        <sphere radius="0.12"/>
      </geometry>
      <material name="light_gray"/>
    </visual>
    <collision>
      <geometry>
        <sphere radius="0.12"/>
      </geometry>
    </collision>
    <inertial>
      <mass value="2.0"/>
      <inertia ixx="0.01" ixy="0" ixz="0" iyy="0.01" iyz="0" izz="0.01"/>
    </inertial>
  </link>
  
  <joint name="neck_joint" type="revolute">
    <parent link="base_link"/>
    <child link="head"/>
    <origin xyz="0 0 1.3" rpy="0 0 0"/>
    <axis xyz="0 0 1"/>
    <limit lower="-1.57" upper="1.57" effort="10" velocity="1.0"/>
  </joint>
  
  <!-- ========== RIGHT ARM ========== -->
  <link name="right_upper_arm">
    <visual>
      <geometry>
        <cylinder radius="0.04" length="0.25"/>
      </geometry>
      <origin xyz="0 0 -0.125" rpy="0 0 0"/>
      <material name="dark_gray"/>
    </visual>
    <inertial>
      <mass value="1.5"/>
      <inertia ixx="0.01" ixy="0" ixz="0" iyy="0.01" iyz="0" izz="0.005"/>
    </inertial>
  </link>
  
  <joint name="right_shoulder_joint" type="revolute">
    <parent link="base_link"/>
    <child link="right_upper_arm"/>
    <origin xyz="0 -0.25 1.1" rpy="0 0 0"/>
    <axis xyz="1 0 0"/>
    <limit lower="-3.14" upper="3.14" effort="50" velocity="2.0"/>
  </joint>
  
  <link name="right_lower_arm">
    <visual>
      <geometry>
        <cylinder radius="0.035" length="0.25"/>
      </geometry>
      <origin xyz="0 0 -0.125" rpy="0 0 0"/>
      <material name="light_gray"/>
    </visual>
    <inertial>
      <mass value="1.0"/>
      <inertia ixx="0.008" ixy="0" ixz="0" iyy="0.008" iyz="0" izz="0.004"/>
    </inertial>
  </link>
  
  <joint name="right_elbow_joint" type="revolute">
    <parent link="right_upper_arm"/>
    <child link="right_lower_arm"/>
    <origin xyz="0 0 -0.25" rpy="0 0 0"/>
    <axis xyz="1 0 0"/>
    <limit lower="0" upper="2.5" effort="30" velocity="2.0"/>
  </joint>
  
  <!-- ========== LEFT ARM ========== -->
  <link name="left_upper_arm">
    <visual>
      <geometry>
        <cylinder radius="0.04" length="0.25"/>
      </geometry>
      <origin xyz="0 0 -0.125" rpy="0 0 0"/>
      <material name="dark_gray"/>
    </visual>
    <inertial>
      <mass value="1.5"/>
      <inertia ixx="0.01" ixy="0" ixz="0" iyy="0.01" iyz="0" izz="0.005"/>
    </inertial>
  </link>
  
  <joint name="left_shoulder_joint" type="revolute">
    <parent link="base_link"/>
    <child link="left_upper_arm"/>
    <origin xyz="0 0.25 1.1" rpy="0 0 0"/>
    <axis xyz="1 0 0"/>
    <limit lower="-3.14" upper="3.14" effort="50" velocity="2.0"/>
  </joint>
  
  <link name="left_lower_arm">
    <visual>
      <geometry>
        <cylinder radius="0.035" length="0.25"/>
      </geometry>
      <origin xyz="0 0 -0.125" rpy="0 0 0"/>
      <material name="light_gray"/>
    </visual>
    <inertial>
      <mass value="1.0"/>
      <inertia ixx="0.008" ixy="0" ixz="0" iyy="0.008" iyz="0" izz="0.004"/>
    </inertial>
  </link>
  
  <joint name="left_elbow_joint" type="revolute">
    <parent link="left_upper_arm"/>
    <child link="left_lower_arm"/>
    <origin xyz="0 0 -0.25" rpy="0 0 0"/>
    <axis xyz="1 0 0"/>
    <limit lower="0" upper="2.5" effort="30" velocity="2.0"/>
  </joint>
  
  <!-- ========== RIGHT LEG ========== -->
  <link name="right_upper_leg">
    <visual>
      <geometry>
        <cylinder radius="0.05" length="0.35"/>
      </geometry>
      <origin xyz="0 0 -0.175" rpy="0 0 0"/>
      <material name="cyan"/>
    </visual>
    <inertial>
      <mass value="3.0"/>
      <inertia ixx="0.03" ixy="0" ixz="0" iyy="0.03" iyz="0" izz="0.01"/>
    </inertial>
  </link>
  
  <joint name="right_hip_joint" type="revolute">
    <parent link="base_link"/>
    <child link="right_upper_leg"/>
    <origin xyz="0 -0.1 0.65" rpy="0 0 0"/>
    <axis xyz="1 0 0"/>
    <limit lower="-1.5" upper="1.5" effort="100" velocity="2.0"/>
  </joint>
  
  <link name="right_lower_leg">
    <visual>
      <geometry>
        <cylinder radius="0.04" length="0.35"/>
      </geometry>
      <origin xyz="0 0 -0.175" rpy="0 0 0"/>
      <material name="dark_gray"/>
    </visual>
    <inertial>
      <mass value="2.0"/>
      <inertia ixx="0.02" ixy="0" ixz="0" iyy="0.02" iyz="0" izz="0.008"/>
    </inertial>
  </link>
  
  <joint name="right_knee_joint" type="revolute">
    <parent link="right_upper_leg"/>
    <child link="right_lower_leg"/>
    <origin xyz="0 0 -0.35" rpy="0 0 0"/>
    <axis xyz="1 0 0"/>
    <limit lower="0" upper="2.5" effort="80" velocity="2.0"/>
  </joint>
  
  <link name="right_foot">
    <visual>
      <geometry>
        <box size="0.2 0.08 0.04"/>
      </geometry>
      <origin xyz="0.05 0 0" rpy="0 0 0"/>
      <material name="blue"/>
    </visual>
    <inertial>
      <mass value="0.5"/>
      <inertia ixx="0.001" ixy="0" ixz="0" iyy="0.002" iyz="0" izz="0.002"/>
    </inertial>
  </link>
  
  <joint name="right_ankle_joint" type="revolute">
    <parent link="right_lower_leg"/>
    <child link="right_foot"/>
    <origin xyz="0 0 -0.35" rpy="0 0 0"/>
    <axis xyz="1 0 0"/>
    <limit lower="-0.8" upper="0.8" effort="50" velocity="2.0"/>
  </joint>
  
  <!-- ========== LEFT LEG ========== -->
  <link name="left_upper_leg">
    <visual>
      <geometry>
        <cylinder radius="0.05" length="0.35"/>
      </geometry>
      <origin xyz="0 0 -0.175" rpy="0 0 0"/>
      <material name="cyan"/>
    </visual>
    <inertial>
      <mass value="3.0"/>
      <inertia ixx="0.03" ixy="0" ixz="0" iyy="0.03" iyz="0" izz="0.01"/>
    </inertial>
  </link>
  
  <joint name="left_hip_joint" type="revolute">
    <parent link="base_link"/>
    <child link="left_upper_leg"/>
    <origin xyz="0 0.1 0.65" rpy="0 0 0"/>
    <axis xyz="1 0 0"/>
    <limit lower="-1.5" upper="1.5" effort="100" velocity="2.0"/>
  </joint>
  
  <link name="left_lower_leg">
    <visual>
      <geometry>
        <cylinder radius="0.04" length="0.35"/>
      </geometry>
      <origin xyz="0 0 -0.175" rpy="0 0 0"/>
      <material name="dark_gray"/>
    </visual>
    <inertial>
      <mass value="2.0"/>
      <inertia ixx="0.02" ixy="0" ixz="0" iyy="0.02" iyz="0" izz="0.008"/>
    </inertial>
  </link>
  
  <joint name="left_knee_joint" type="revolute">
    <parent link="left_upper_leg"/>
    <child link="left_lower_leg"/>
    <origin xyz="0 0 -0.35" rpy="0 0 0"/>
    <axis xyz="1 0 0"/>
    <limit lower="0" upper="2.5" effort="80" velocity="2.0"/>
  </joint>
  
  <link name="left_foot">
    <visual>
      <geometry>
        <box size="0.2 0.08 0.04"/>
      </geometry>
      <origin xyz="0.05 0 0" rpy="0 0 0"/>
      <material name="blue"/>
    </visual>
    <inertial>
      <mass value="0.5"/>
      <inertia ixx="0.001" ixy="0" ixz="0" iyy="0.002" iyz="0" izz="0.002"/>
    </inertial>
  </link>
  
  <joint name="left_ankle_joint" type="revolute">
    <parent link="left_lower_leg"/>
    <child link="left_foot"/>
    <origin xyz="0 0 -0.35" rpy="0 0 0"/>
    <axis xyz="1 0 0"/>
    <limit lower="-0.8" upper="0.8" effort="50" velocity="2.0"/>
  </joint>

</robot>
